<?xml version="1.0"?>
<robot xmlns:xacro="http://www.ros.org/wiki/xacro">
    <xacro:property name="sphere_radius" value="0.025"/>
    <xacro:property name="sphere_mass" value="0.05"/>
    <xacro:property name="sphere_inertia" value="0.0001 0.0 0.0 0.0001 0.0 0.0001"/>

    <xacro:property name="steering_size" value="0.1 0.2 0.05"/>
    <xacro:property name="steering_mass" value="0.2"/>
    <xacro:property name="steering_inertia" value="0.002 0.0 0.0 0.002 0.0 0.002"/>

    <!-- Link for the sphere -->
    <link name="steering_sphere">
      <visual>
        <geometry>
          <sphere radius="${sphere_radius}"/>
        </geometry>
        <material name="blue"/>
      </visual>
      <collision>
        <geometry>
          <sphere radius="${sphere_radius}"/>
        </geometry>
      </collision>
      <inertial>
        <mass value="${sphere_mass}"/>
        <inertia ixx="${sphere_inertia.split(' ')[0]}" ixy="${sphere_inertia.split(' ')[1]}" ixz="${sphere_inertia.split(' ')[2]}" 
                iyy="${sphere_inertia.split(' ')[3]}" iyz="${sphere_inertia.split(' ')[4]}" izz="${sphere_inertia.split(' ')[5]}"/>
      </inertial>
    </link>
    <gazebo reference="steering_sphere">
      <material>Gazebo/Blue</material>
    </gazebo>

    <!-- Joint connecting the sphere to the base link -->
    <joint name="sphere_to_base_joint" type="fixed">
      <parent link="base_link"/>
      <child link="steering_sphere"/>
      <origin xyz="0.225 0 0"/>
    </joint>

    <!-- Joint connecting the sphere to the steering mechanism -->
    <joint name="sphere_to_steering_joint" type="revolute">
      <parent link="steering_sphere"/>
      <child link="front_wheel_steering_link"/>
      <origin xyz="0.075 0 0"/> <!-- Position the sphere below the steering mechanism -->
      <axis xyz="0 0 1"/> <!-- Define the axis of rotation -->
      <limit lower="-0.75" upper="0.75" effort="1.0" velocity="1.0"/> <!-- Define the limits, effort, and velocity -->
    </joint>

    <!-- Link for the steering mechanism -->
    <link name="front_wheel_steering_link">
      <visual>
        <geometry>
          <box size="${steering_size}"/>
        </geometry>
        <material name="gray"/>
      </visual>
      <collision>
        <geometry>
          <box size="${steering_size}"/>
        </geometry>
      </collision>
      <inertial>
        <mass value="${steering_mass}"/>
        <inertia ixx="${steering_inertia.split(' ')[0]}" ixy="${steering_inertia.split(' ')[1]}" ixz="${steering_inertia.split(' ')[2]}" 
                iyy="${steering_inertia.split(' ')[3]}" iyz="${steering_inertia.split(' ')[4]}" izz="${steering_inertia.split(' ')[5]}"/>
      </inertial>
    </link>
     <gazebo reference="front_wheel_steering_link">
    <material>Gazebo/Gray</material>
    </gazebo>

    <!-- Joints for the front wheels attached to the steering mechanism -->
    <joint name="front_left_wheel_steering_joint" type="continuous">
      <parent link="front_wheel_steering_link"/>
      <child link="front_left_wheel"/>
      <origin xyz="0 -0.125 0"/>
      <axis xyz="0 1 0"/>
    </joint>

    <joint name="front_right_wheel_steering_joint" type="continuous">
      <parent link="front_wheel_steering_link"/>
      <child link="front_right_wheel"/>
      <origin xyz="0 0.125 0"/>
      <axis xyz="0 1 0"/>
    </joint>

</robot>
