<?xml version="1.0"?>
<robot xmlns:xacro="http://www.ros.org/wiki/xacro">
    <xacro:property name="wheel_radius" value="0.075"/>
    <xacro:property name="wheel_length" value="0.05"/>
    <xacro:property name="wheel_mass" value="0.1"/>
    <xacro:property name="wheel_inertia" value="0.001 0.0 0.0 0.001 0.0 0.001"/>

    <xacro:property name="blx" value="-0.2"/>
    <xacro:property name="bly" value="-0.125"/>
    <xacro:property name="blz" value="0"/>

    <xacro:property name="brx" value="-0.2"/>
    <xacro:property name="bry" value="0.125"/>
    <xacro:property name="brz" value="0"/>

    <xacro:property name="flx" value="0"/>
    <xacro:property name="fly" value="-0.125"/>
    <xacro:property name="flz" value="0"/>

    <xacro:property name="frx" value="0"/>
    <xacro:property name="fry" value="-0.125"/>
    <xacro:property name="frz" value="0"/>

    <link name="back_left_wheel">
      <visual>
        <origin rpy="0.0 ${pi/2} ${pi/2}"/>
        <geometry>
          <cylinder length="${wheel_length}" radius="${wheel_radius}"/>
        </geometry>
        <material name="black"/>
      </visual>
      <collision>
        <origin rpy="0.0 ${pi/2} ${pi/2}"/>
        <geometry>
          <cylinder length="${wheel_length}" radius="${wheel_radius}"/>
        </geometry>
      </collision>
      <inertial>
        <mass value="${wheel_mass}"/>
        <inertia ixx="${wheel_inertia.split(' ')[0]}" ixy="${wheel_inertia.split(' ')[1]}" ixz="${wheel_inertia.split(' ')[2]}" 
                iyy="${wheel_inertia.split(' ')[3]}" iyz="${wheel_inertia.split(' ')[4]}" izz="${wheel_inertia.split(' ')[5]}"/>
      </inertial>
    </link>
     <gazebo reference="back_left_wheel">
    <material>Gazebo/Black</material>
  </gazebo>

    <joint name="back_left_wheel_joint" type="continuous">
      <parent link="base_link"/>
      <child link="back_left_wheel"/>
      <origin xyz="${blx} ${bly} ${blz}"/>
      <axis xyz="0 1 0"/>
    </joint>

    <link name="back_right_wheel">
      <visual>
        <origin rpy="0.0 ${pi/2} ${pi/2}"/>
        <geometry>
          <cylinder length="${wheel_length}" radius="${wheel_radius}"/>
        </geometry>
        <material name="black"/>
      </visual>
      <collision>
        <origin rpy="0.0 ${pi/2} ${pi/2}"/>
        <geometry>
          <cylinder length="${wheel_length}" radius="${wheel_radius}"/>
        </geometry>
      </collision>
      <inertial>
        <mass value="${wheel_mass}"/>
        <inertia ixx="${wheel_inertia.split(' ')[0]}" ixy="${wheel_inertia.split(' ')[1]}" ixz="${wheel_inertia.split(' ')[2]}" 
                iyy="${wheel_inertia.split(' ')[3]}" iyz="${wheel_inertia.split(' ')[4]}" izz="${wheel_inertia.split(' ')[5]}"/>
      </inertial>
    </link>
     <gazebo reference="back_right_wheel">
    <material>Gazebo/Black</material>
  </gazebo>

    <joint name="back_right_wheel_joint" type="continuous">
      <parent link="base_link"/>
      <child link="back_right_wheel"/>
      <origin xyz="${brx} ${bry} ${brz}"/>
      <axis xyz="0 1 0"/>
    </joint>

  <link name="front_left_wheel">
      <visual>
        <origin rpy="0.0 ${pi/2} ${pi/2}"/>
        <geometry>
          <cylinder length="${wheel_length}" radius="${wheel_radius}"/>
        </geometry>
        <material name="black"/>
      </visual>
      <collision>
        <origin rpy="0.0 ${pi/2} ${pi/2}"/>
        <geometry>
          <cylinder length="${wheel_length}" radius="${wheel_radius}"/>
        </geometry>
      </collision>
      <inertial>
        <mass value="${wheel_mass}"/>
        <inertia ixx="${wheel_inertia.split(' ')[0]}" ixy="${wheel_inertia.split(' ')[1]}" ixz="${wheel_inertia.split(' ')[2]}" 
                iyy="${wheel_inertia.split(' ')[3]}" iyz="${wheel_inertia.split(' ')[4]}" izz="${wheel_inertia.split(' ')[5]}"/>
      </inertial>
    </link>
     <gazebo reference="front_left_wheel">
    <material>Gazebo/Black</material>
  </gazebo>

    <joint name="front_left_wheel_joint" type="continuous">
      <parent link="front_wheel_steering_link"/>
      <child link="front_left_wheel"/>
      <origin xyz="${flx} ${fly} ${flz}"/>
      <axis xyz="0 1 0"/>
    </joint>

<link name="front_right_wheel">
      <visual>
        <origin rpy="0.0 ${pi/2} ${pi/2}"/>
        <geometry>
          <cylinder length="${wheel_length}" radius="${wheel_radius}"/>
        </geometry>
        <material name="black"/>
      </visual>
      <collision>
        <origin rpy="0.0 ${pi/2} ${pi/2}"/>
        <geometry>
          <cylinder length="${wheel_length}" radius="${wheel_radius}"/>
        </geometry>
      </collision>
      <inertial>
        <mass value="${wheel_mass}"/>
        <inertia ixx="${wheel_inertia.split(' ')[0]}" ixy="${wheel_inertia.split(' ')[1]}" ixz="${wheel_inertia.split(' ')[2]}" 
                iyy="${wheel_inertia.split(' ')[3]}" iyz="${wheel_inertia.split(' ')[4]}" izz="${wheel_inertia.split(' ')[5]}"/>
      </inertial>
    </link>
     <gazebo reference="front_right_wheel">
    <material>Gazebo/Black</material>
  </gazebo>

    <joint name="front_right_wheel_joint" type="continuous">
      <parent link="front_wheel_steering_link"/>
      <child link="front_right_wheel"/>
      <origin xyz="${frx} ${fry} ${frz}"/>
      <axis xyz="0 1 0"/>
    </joint>

</robot>
